# should future.wait() throw an exception on remote errors?
throw_remote_exceptions = True


